Workbook

Sheet Summary
A1: Afterhours — Financial Model Summary
A2: Base case: organic-only runway, no pre-seed assumed to close, founders unpaid. v3, baseline refreshed 2026-07-01.
A3: Year 1 acquisition spend by channel | D3: Year 1 acquisition spend by channel
A4: Traction today (2026-07-01) | D4: Generic ads/ambassadors | E4: ='Income Statement'!N26
A5: Total signups | B5: =Assumptions!$C$10 | D5: Creator partnerships | E5: ='Income Statement'!N27
A6: Verified users | B6: =Assumptions!$C$11 | D6: r/girlshangouthyd sponsorship | E6: ='Income Statement'!N28
A7: Active users | B7: =Assumptions!$C$13 | D7: Total acquisition spend, Year 1 | E7: ='Income Statement'!N29
A8: Spend to date | B8: =Assumptions!$C$14
A10: Month 12 projection
A11: Cumulative verified users | B11: ='Users & Growth'!M13
A12: Active users | B12: ='Users & Growth'!M16
A13: Monthly revenue | B13: ='Income Statement'!M10
A14: Monthly burn | B14: =-'Income Statement'!M45
A16: Year 1 totals & funding need
A17: Year 1 total revenue | B17: ='Income Statement'!N10
A18: Year 1 total burn | B18: =ABS('Income Statement'!N45)
A19: Founder funding required | B19: ='Balance Sheet'!M14
A20: LTV : CAC, Month 12 (activation-adj) | B20: ='Unit Economics & Break-Even'!M15
A23: Notes
A24: Break-even is not reached within 12 months in this base case (see Unit Economics & Break-Even).
A25: Paid-event assumptions (15% paid, ₹400 ticket, 17.5% commission) are placeholders — replace once real paid events run.
A26: Cash on hand is ₹0 and the pre-seed round is not assumed to close — 'Founder funding required' is the real money needed.
A27: Creator (33/deal) and sponsorship (20/event) signup estimates have no real data behind them yet.
A28: Host sponsorship only works if RSVPs are required through the app, not WhatsApp as usual.
A29: The $25k YC AI Stack credit covers AWS/Supabase/AI infra only, not salaries or marketing.
A31: Tabs: Assumptions → Users & Growth → Revenue Model → Income Statement → Cash Flow → Balance Sheet → Unit Economics & Break-Even → Financial Ratios → Cap Table.

Sheet Assumptions
A1: Afterhours — Financial Model Assumptions
A2: All figures INR unless noted. Blue = input, hover a cell for context. Baseline + funnel rates refreshed 2026-07-01 vs real prod Supabase data (Rory Sutherland review pull), then adjusted for ~10 men who signed up but never verify and for a modestly better marketing funnel than the original single Reddit post. All other assumptions unchanged from 2026-06-22.
A4: Company & model setup
A5: Number of founders | C5: 5
A6: Founder monthly salary (each) | C6: 0
A7: USD→INR rate | C7: 83
A9: Current traction — Month 0 actuals (2026-06-22)
A10: Total signups | C10: 65
A11: Verified users | C11: 26
A12: Verification rate | C12: =C11/C10
A13: Active users | C13: 6
A14: CAC to date | C14: 0
A16: Acquisition — organic & generic paid
A17: Organic signups, Month 1 | C17: 25
A18: Organic signups MoM growth | C18: 0.08
A19: Generic paid budget / month | C19: 20000
A20: Blended CAC, Months 1-2 | C20: 150
A21: Blended CAC, Month 3+ | C21: 100
A22: Verification rate, all new signups | C22: 0.5
A23: 2nd-city launch month | C23: 7
A24: 2nd-city one-time launch cost | C24: 75000
A25: 2nd-city signup uplift | C25: 0.15
A27: Acquisition — creator partnerships (10-20k followers)
A28: Start month | C28: 2
A29: Cost / deal | C29: 6000
A30: Signups / deal | C30: 33
A31: Deals/month, pilot tier | C31: 1
A32: Ramp-up month | C32: 6
A33: Deals/month, scaled tier | C33: 4
A35: Acquisition — r/girlshangouthyd host sponsorship
A36: Start month | C36: 1
A37: Sponsored events/month | C37: 2
A38: Cost / event | C38: 4500
A39: Signups / event | C39: 20
A41: Engagement & retention
A42: Monthly active-user churn | C42: 0.25
A43: Activation rate (new verified → active) | C43: 0.3
A44: Events attended / active user / month | C44: 1
A45: Share of actives hosting ≥1 event/month | C45: 0.1
A47: Revenue model
...

Sheet Users & Growth
A1: Users & Growth
A2: Monthly acquisition → verification → activation → retention funnel.
A4: (₹000s) | B4: 1 | C4: 2 | D4: 3 | E4: 4 | F4: 5 | G4: 6 | H4: 7 | I4: 8 | J4: 9 | K4: 10 | L4: 11 | M4: 12 | N4: FY1
A6: Organic new signups | B6: =Assumptions!$C$17 | C6: =B6*(1+Assumptions!$C$18) | D6: =C6*(1+Assumptions!$C$18) | E6: =D6*(1+Assumptions!$C$18) | F6: =E6*(1+Assumptions!$C$18) | G6: =F6*(1+Assumptions!$C$18) | H6: =G6*(1+Assumptions!$C$18) | I6: =H6*(1+Assumptions!$C$18) | J6: =I6*(1+Assumptions!$C$18) | ... M6: =L6*(1+Assumptions!$C$18) | N6: =SUM(B6:M6)
A7: Generic paid new signups | B7: =Assumptions!$C$19/IF(B$4<Assumptions!$C$68,Assumptions!$C$20,Assumptions!$C$21) | C7: =Assumptions!$C$19/IF(C$4<Assumptions!$C$68,Assumptions!$C$20,Assumptions!$C$21) | D7: =Assumptions!$C$19/IF(D$4<Assumptions!$C$68,Assumptions!$C$20,Assumptions!$C$21) | E7: =Assumptions!$C$19/IF(E$4<Assumptions!$C$68,Assumptions!$C$20,Assumptions!$C$21) | F7: =Assumptions!$C$19/IF(F$4<Assumptions!$C$68,Assumptions!$C$20,Assumptions!$C$21) | G7: =Assumptions!$C$19/IF(G$4<Assumptions!$C$68,Assumptions!$C$20,Assumptions!$C$21) | H7: =Assumptions!$C$19/IF(H$4<Assumptions!$C$68,Assumptions!$C$20,Assumptions!$C$21) | I7: =Assumptions!$C$19/IF(I$4<Assumptions!$C$68,Assumptions!$C$20,Assumptions!$C$21) | ... M7: =Assumptions!$C$19/IF(M$4<Assumptions!$C$68,Assumptions!$C$20,Assumptions!$C$21) | N7: =SUM(B7:M7)
A8: 2nd-city uplift × | B8: =IF(B$4>=Assumptions!$C$23,1+Assumptions!$C$25,1) | C8: =IF(C$4>=Assumptions!$C$23,1+Assumptions!$C$25,1) | D8: =IF(D$4>=Assumptions!$C$23,1+Assumptions!$C$25,1) | E8: =IF(E$4>=Assumptions!$C$23,1+Assumptions!$C$25,1) | F8: =IF(F$4>=Assumptions!$C$23,1+Assumptions!$C$25,1) | G8: =IF(G$4>=Assumptions!$C$23,1+Assumptions!$C$25,1) | H8: =IF(H$4>=Assumptions!$C$23,1+Assumptions!$C$25,1) | I8: =IF(I$4>=Assumptions!$C$23,1+Assumptions!$C$25,1) | ... M8: =IF(M$4>=Assumptions!$C$23,1+Assumptions!$C$25,1)
A9: Creator-partnership new signups | B9: =IF(B$4<Assumptions!$C$28,0,IF(B$4<Assumptions!$C$32,Assumptions!$C$31,Assumptions!$C$33))*Assumptions!$C$30 | C9: =IF(C$4<Assumptions!$C$28,0,IF(C$4<Assumptions!$C$32,Assumptions!$C$31,Assumptions!$C$33))*Assumptions!$C$30 | D9: =IF(D$4<Assumptions!$C$28,0,IF(D$4<Assumptions!$C$32,Assumptions!$C$31,Assumptions!$C$33))*Assumptions!$C$30 | E9: =IF(E$4<Assumptions!$C$28,0,IF(E$4<Assumptions!$C$32,Assumptions!$C$31,Assumptions!$C$33))*Assumptions!$C$30 | F9: =IF(F$4<Assumptions!$C$28,0,IF(F$4<Assumptions!$C$32,Assumptions!$C$31,Assumptions!$C$33))*Assumptions!$C$30 | G9: =IF(G$4<Assumptions!$C$28,0,IF(G$4<Assumptions!$C$32,Assumptions!$C$31,Assumptions!$C$33))*Assumptions!$C$30 | H9: =IF(H$4<Assumptions!$C$28,0,IF(H$4<Assumptions!$C$32,Assumptions!$C$31,Assumptions!$C$33))*Assumptions!$C$30 | I9: =IF(I$4<Assumptions!$C$28,0,IF(I$4<Assumptions!$C$32,Assumptions!$C$31,Assumptions!$C$33))*Assumptions!$C$30 | ... M9: =IF(M$4<Assumptions!$C$28,0,IF(M$4<Assumptions!$C$32,Assumptions!$C$31,Assumptions!$C$33))*Assumptions!$C$30 | N9: =SUM(B9:M9)
A10: Host-sponsorship new signups | B10: =IF(B$4<Assumptions!$C$36,0,Assumptions!$C$37)*Assumptions!$C$39 | C10: =IF(C$4<Assumptions!$C$36,0,Assumptions!$C$37)*Assumptions!$C$39 | D10: =IF(D$4<Assumptions!$C$36,0,Assumptions!$C$37)*Assumptions!$C$39 | E10: =IF(E$4<Assumptions!$C$36,0,Assumptions!$C$37)*Assumptions!$C$39 | F10: =IF(F$4<Assumptions!$C$36,0,Assumptions!$C$37)*Assumptions!$C$39 | G10: =IF(G$4<Assumptions!$C$36,0,Assumptions!$C$37)*Assumptions!$C$39 | H10: =IF(H$4<Assumptions!$C$36,0,Assumptions!$C$37)*Assumptions!$C$39 | I10: =IF(I$4<Assumptions!$C$36,0,Assumptions!$C$37)*Assumptions!$C$39 | ... M10: =IF(M$4<Assumptions!$C$36,0,Assumptions!$C$37)*Assumptions!$C$39 | N10: =SUM(B10:M10)
A11: Total new signups (incl. referrals) | B11: =(B6+B7)*B8+B9+B10+Assumptions!$C$13*Assumptions!$C$96 | C11: =(C6+C7)*C8+C9+C10+B16*Assumptions!$C$96 | D11: =(D6+D7)*D8+D9+D10+C16*Assumptions!$C$96 | E11: =(E6+E7)*E8+E9+E10+D16*Assumptions!$C$96 | F11: =(F6+F7)*F8+F9+F10+E16*Assumptions!$C$96 | G11: =(G6+G7)*G8+G9+G10+F16*Assumptions!$C$96 | H11: =(H6+H7)*H8+H9+H10+G16*Assumptions!$C$96 | I11: =(I6+I7)*I8+I9+I10+H16*Assumptions!$C$96 | J11: =(J6+J7)*J8+J9+J10+I16*Assumptions!$C$96 | ... M11: =(M6+M7)*M8+M9+M10+L16*Assumptions!$C$96 | N11: =SUM(B11:M11)
A12: New verified users | B12: =B11*Assumptions!$C$22 | C12: =C11*Assumptions!$C$22 | D12: =D11*Assumptions!$C$22 | E12: =E11*Assumptions!$C$22 | F12: =F11*Assumptions!$C$22 | G12: =G11*Assumptions!$C$22 | H12: =H11*Assumptions!$C$22 | I12: =I11*Assumptions!$C$22 | ... M12: =M11*Assumptions!$C$22 | N12: =SUM(B12:M12)
A13: Cumulative verified users | B13: =Assumptions!$C$11+B12 | C13: =B13+C12 | D13: =C13+D12 | E13: =D13+E12 | F13: =E13+F12 | G13: =F13+G12 | H13: =G13+H12 | I13: =H13+I12 | J13: =I13+J12 | ... M13: =L13+M12 | N13: =M13
A15: New active users (activation) | B15: =B12*IF(B$4>=Assumptions!$C$90,Assumptions!$C$91,Assumptions!$C$43) | C15: =C12*IF(C$4>=Assumptions!$C$90,Assumptions!$C$91,Assumptions!$C$43) | D15: =D12*IF(D$4>=Assumptions!$C$90,Assumptions!$C$91,Assumptions!$C$43) | E15: =E12*IF(E$4>=Assumptions!$C$90,Assumptions!$C$91,Assumptions!$C$43) | F15: =F12*IF(F$4>=Assumptions!$C$90,Assumptions!$C$91,Assumptions!$C$43) | G15: =G12*IF(G$4>=Assumptions!$C$90,Assumptions!$C$91,Assumptions!$C$43) | H15: =H12*IF(H$4>=Assumptions!$C$90,Assumptions!$C$91,Assumptions!$C$43) | I15: =I12*IF(I$4>=Assumptions!$C$90,Assumptions!$C$91,Assumptions!$C$43) | ... M15: =M12*IF(M$4>=Assumptions!$C$90,Assumptions!$C$91,Assumptions!$C$43) | N15: =SUM(B15:M15)
A16: Active users, end of month | B16: =Assumptions!$C$13*(1-IF(B$4>=Assumptions!$C$90,Assumptions!$C$93,Assumptions!$C$42))+B15 | C16: =B16*(1-IF(C$4>=Assumptions!$C$90,Assumptions!$C$93,Assumptions!$C$42))+C15 | D16: =C16*(1-IF(D$4>=Assumptions!$C$90,Assumptions!$C$93,Assumptions!$C$42))+D15 | E16: =D16*(1-IF(E$4>=Assumptions!$C$90,Assumptions!$C$93,Assumptions!$C$42))+E15 | F16: =E16*(1-IF(F$4>=Assumptions!$C$90,Assumptions!$C$93,Assumptions!$C$42))+F15 | G16: =F16*(1-IF(G$4>=Assumptions!$C$90,Assumptions!$C$93,Assumptions!$C$42))+G15 | H16: =G16*(1-IF(H$4>=Assumptions!$C$90,Assumptions!$C$93,Assumptions!$C$42))+H15 | I16: =H16*(1-IF(I$4>=Assumptions!$C$90,Assumptions!$C$93,Assumptions!$C$42))+I15 | J16: =I16*(1-IF(J$4>=Assumptions!$C$90,Assumptions!$C$93,Assumptions!$C$42))+J15 | ... M16: =L16*(1-IF(M$4>=Assumptions!$C$90,Assumptions!$C$93,Assumptions!$C$42))+M15 | N16: =M16
A17: Active users, MoM growth | B17: =IFERROR(B16/Assumptions!$C$13-1,"") | C17: =IFERROR(C16/B16-1,"") | D17: =IFERROR(D16/C16-1,"") | E17: =IFERROR(E16/D16-1,"") | F17: =IFERROR(F16/E16-1,"") | G17: =IFERROR(G16/F16-1,"") | H17: =IFERROR(H16/G16-1,"") | I17: =IFERROR(I16/H16-1,"") | J17: =IFERROR(J16/I16-1,"") | ... M17: =IFERROR(M16/L16-1,"")
A19: Events created | B19: =B16*Assumptions!$C$45 | C19: =C16*Assumptions!$C$45 | D19: =D16*Assumptions!$C$45 | E19: =E16*Assumptions!$C$45 | F19: =F16*Assumptions!$C$45 | G19: =G16*Assumptions!$C$45 | H19: =H16*Assumptions!$C$45 | I19: =I16*Assumptions!$C$45 | ... M19: =M16*Assumptions!$C$45 | N19: =SUM(B19:M19)
A20: Total event-attendances | B20: =B16*IF(B$4>=Assumptions!$C$90,Assumptions!$C$92,Assumptions!$C$44) | C20: =C16*IF(C$4>=Assumptions!$C$90,Assumptions!$C$92,Assumptions!$C$44) | D20: =D16*IF(D$4>=Assumptions!$C$90,Assumptions!$C$92,Assumptions!$C$44) | E20: =E16*IF(E$4>=Assumptions!$C$90,Assumptions!$C$92,Assumptions!$C$44) | F20: =F16*IF(F$4>=Assumptions!$C$90,Assumptions!$C$92,Assumptions!$C$44) | G20: =G16*IF(G$4>=Assumptions!$C$90,Assumptions!$C$92,Assumptions!$C$44) | H20: =H16*IF(H$4>=Assumptions!$C$90,Assumptions!$C$92,Assumptions!$C$44) | I20: =I16*IF(I$4>=Assumptions!$C$90,Assumptions!$C$92,Assumptions!$C$44) | ... M20: =M16*IF(M$4>=Assumptions!$C$90,Assumptions!$C$92,Assumptions!$C$44) | N20: =SUM(B20:M20)
A21: Paid event-attendances | B21: =B20*Assumptions!$C$48 | C21: =C20*Assumptions!$C$48 | D21: =D20*Assumptions!$C$48 | E21: =E20*Assumptions!$C$48 | F21: =F20*Assumptions!$C$48 | G21: =G20*Assumptions!$C$48 | H21: =H20*Assumptions!$C$48 | I21: =I20*Assumptions!$C$48 | ... M21: =M20*Assumptions!$C$48 | N21: =SUM(B21:M21)

Sheet Revenue Model
A1: Revenue Model
A2: Commission, subscription and B2B sponsorship, by stream.
A4: (₹000s) | B4: 1 | C4: 2 | D4: 3 | E4: 4 | F4: 5 | G4: 6 | H4: 7 | I4: 8 | J4: 9 | K4: 10 | L4: 11 | M4: 12 | N4: FY1
A6: Commission on paid events
A7: Paid-ticket GMV | B7: ='Users & Growth'!B21*Assumptions!$C$49 | C7: ='Users & Growth'!C21*Assumptions!$C$49 | D7: ='Users & Growth'!D21*Assumptions!$C$49 | E7: ='Users & Growth'!E21*Assumptions!$C$49 | F7: ='Users & Growth'!F21*Assumptions!$C$49 | G7: ='Users & Growth'!G21*Assumptions!$C$49 | H7: ='Users & Growth'!H21*Assumptions!$C$49 | I7: ='Users & Growth'!I21*Assumptions!$C$49 | ... M7: ='Users & Growth'!M21*Assumptions!$C$49 | N7: =SUM(B7:M7)
A8: Commission revenue | B8: =B7*Assumptions!$C$50 | C8: =C7*Assumptions!$C$50 | D8: =D7*Assumptions!$C$50 | E8: =E7*Assumptions!$C$50 | F8: =F7*Assumptions!$C$50 | G8: =G7*Assumptions!$C$50 | H8: =H7*Assumptions!$C$50 | I8: =I7*Assumptions!$C$50 | ... M8: =M7*Assumptions!$C$50 | N8: =SUM(B8:M8)
A9: Payment-gateway fees (COGS) | B9: =B7*Assumptions!$C$51 | C9: =C7*Assumptions!$C$51 | D9: =D7*Assumptions!$C$51 | E9: =E7*Assumptions!$C$51 | F9: =F7*Assumptions!$C$51 | G9: =G7*Assumptions!$C$51 | H9: =H7*Assumptions!$C$51 | I9: =I7*Assumptions!$C$51 | ... M9: =M7*Assumptions!$C$51 | N9: =SUM(B9:M9)
A11: Premium subscription
A12: Adoption rate, % active users | B12: =IF(B$4<Assumptions!$C$53,0,Assumptions!$C$54+(Assumptions!$C$55-Assumptions!$C$54)*(B$4-Assumptions!$C$53)/(12-Assumptions!$C$53)) | C12: =IF(C$4<Assumptions!$C$53,0,Assumptions!$C$54+(Assumptions!$C$55-Assumptions!$C$54)*(C$4-Assumptions!$C$53)/(12-Assumptions!$C$53)) | D12: =IF(D$4<Assumptions!$C$53,0,Assumptions!$C$54+(Assumptions!$C$55-Assumptions!$C$54)*(D$4-Assumptions!$C$53)/(12-Assumptions!$C$53)) | E12: =IF(E$4<Assumptions!$C$53,0,Assumptions!$C$54+(Assumptions!$C$55-Assumptions!$C$54)*(E$4-Assumptions!$C$53)/(12-Assumptions!$C$53)) | F12: =IF(F$4<Assumptions!$C$53,0,Assumptions!$C$54+(Assumptions!$C$55-Assumptions!$C$54)*(F$4-Assumptions!$C$53)/(12-Assumptions!$C$53)) | G12: =IF(G$4<Assumptions!$C$53,0,Assumptions!$C$54+(Assumptions!$C$55-Assumptions!$C$54)*(G$4-Assumptions!$C$53)/(12-Assumptions!$C$53)) | H12: =IF(H$4<Assumptions!$C$53,0,Assumptions!$C$54+(Assumptions!$C$55-Assumptions!$C$54)*(H$4-Assumptions!$C$53)/(12-Assumptions!$C$53)) | I12: =IF(I$4<Assumptions!$C$53,0,Assumptions!$C$54+(Assumptions!$C$55-Assumptions!$C$54)*(I$4-Assumptions!$C$53)/(12-Assumptions!$C$53)) | ... M12: =IF(M$4<Assumptions!$C$53,0,Assumptions!$C$54+(Assumptions!$C$55-Assumptions!$C$54)*(M$4-Assumptions!$C$53)/(12-Assumptions!$C$53))
A13: Subscription revenue | B13: ='Users & Growth'!B16*B12*Assumptions!$C$52 | C13: ='Users & Growth'!C16*C12*Assumptions!$C$52 | D13: ='Users & Growth'!D16*D12*Assumptions!$C$52 | E13: ='Users & Growth'!E16*E12*Assumptions!$C$52 | F13: ='Users & Growth'!F16*F12*Assumptions!$C$52 | G13: ='Users & Growth'!G16*G12*Assumptions!$C$52 | H13: ='Users & Growth'!H16*H12*Assumptions!$C$52 | I13: ='Users & Growth'!I16*I12*Assumptions!$C$52 | ... M13: ='Users & Growth'!M16*M12*Assumptions!$C$52 | N13: =SUM(B13:M13)
A15: B2B sponsorships
A16: Deals | B16: =IF(B$4<Assumptions!$C$56,0,IF(B$4<Assumptions!$C$57,Assumptions!$C$58,Assumptions!$C$59)) | C16: =IF(C$4<Assumptions!$C$56,0,IF(C$4<Assumptions!$C$57,Assumptions!$C$58,Assumptions!$C$59)) | D16: =IF(D$4<Assumptions!$C$56,0,IF(D$4<Assumptions!$C$57,Assumptions!$C$58,Assumptions!$C$59)) | E16: =IF(E$4<Assumptions!$C$56,0,IF(E$4<Assumptions!$C$57,Assumptions!$C$58,Assumptions!$C$59)) | F16: =IF(F$4<Assumptions!$C$56,0,IF(F$4<Assumptions!$C$57,Assumptions!$C$58,Assumptions!$C$59)) | G16: =IF(G$4<Assumptions!$C$56,0,IF(G$4<Assumptions!$C$57,Assumptions!$C$58,Assumptions!$C$59)) | H16: =IF(H$4<Assumptions!$C$56,0,IF(H$4<Assumptions!$C$57,Assumptions!$C$58,Assumptions!$C$59)) | I16: =IF(I$4<Assumptions!$C$56,0,IF(I$4<Assumptions!$C$57,Assumptions!$C$58,Assumptions!$C$59)) | ... M16: =IF(M$4<Assumptions!$C$56,0,IF(M$4<Assumptions!$C$57,Assumptions!$C$58,Assumptions!$C$59))
A17: Avg deal value | B17: =IF(B$4<Assumptions!$C$56,0,IF(B$4<Assumptions!$C$57,Assumptions!$C$60,Assumptions!$C$61)) | C17: =IF(C$4<Assumptions!$C$56,0,IF(C$4<Assumptions!$C$57,Assumptions!$C$60,Assumptions!$C$61)) | D17: =IF(D$4<Assumptions!$C$56,0,IF(D$4<Assumptions!$C$57,Assumptions!$C$60,Assumptions!$C$61)) | E17: =IF(E$4<Assumptions!$C$56,0,IF(E$4<Assumptions!$C$57,Assumptions!$C$60,Assumptions!$C$61)) | F17: =IF(F$4<Assumptions!$C$56,0,IF(F$4<Assumptions!$C$57,Assumptions!$C$60,Assumptions!$C$61)) | G17: =IF(G$4<Assumptions!$C$56,0,IF(G$4<Assumptions!$C$57,Assumptions!$C$60,Assumptions!$C$61)) | H17: =IF(H$4<Assumptions!$C$56,0,IF(H$4<Assumptions!$C$57,Assumptions!$C$60,Assumptions!$C$61)) | I17: =IF(I$4<Assumptions!$C$56,0,IF(I$4<Assumptions!$C$57,Assumptions!$C$60,Assumptions!$C$61)) | ... M17: =IF(M$4<Assumptions!$C$56,0,IF(M$4<Assumptions!$C$57,Assumptions!$C$60,Assumptions!$C$61))
A18: Sponsorship revenue | B18: =B16*B17 | C18: =C16*C17 | D18: =D16*D17 | E18: =E16*E17 | F18: =F16*F17 | G18: =G16*G17 | H18: =H16*H17 | I18: =I16*I17 | ... M18: =M16*M17 | N18: =SUM(B18:M18)
A20: Totals
A21: Total Revenue | B21: =B8+B13+B18 | C21: =C8+C13+C18 | D21: =D8+D13+D18 | E21: =E8+E13+E18 | F21: =F8+F13+F18 | G21: =G8+G13+G18 | H21: =H8+H13+H18 | I21: =I8+I13+I18 | ... M21: =M8+M13+M18 | N21: =SUM(B21:M21)
A22: Total COGS | B22: =B9 | C22: =C9 | D22: =D9 | E22: =E9 | F22: =F9 | G22: =G9 | H22: =H9 | I22: =I9 | ... M22: =M9 | N22: =SUM(B22:M22)
A23: Gross Profit | B23: =B21-B22 | C23: =C21-C22 | D23: =D21-D22 | E23: =E21-E22 | F23: =F21-F22 | G23: =G21-G22 | H23: =H21-H22 | I23: =I21-I22 | ... M23: =M21-M22 | N23: =SUM(B23:M23)
A24: Gross Margin % | B24: =IFERROR(B23/B21,"") | C24: =IFERROR(C23/C21,"") | D24: =IFERROR(D23/D21,"") | E24: =IFERROR(E23/E21,"") | F24: =IFERROR(F23/F21,"") | G24: =IFERROR(G23/G21,"") | H24: =IFERROR(H23/H21,"") | I24: =IFERROR(I23/I21,"") | ... M24: =IFERROR(M23/M21,"")

Sheet Income Statement
A1: Income Statement
A2: Monthly P&L, 12-month forecast. No D&A/interest/tax — pre-revenue startup, losses carried forward.
A4: (₹000s) | B4: 1 | C4: 2 | D4: 3 | E4: 4 | F4: 5 | G4: 6 | H4: 7 | I4: 8 | J4: 9 | K4: 10 | L4: 11 | M4: 12 | N4: FY1
A6: Revenue
A7: Commission revenue | B7: ='Revenue Model'!B8 | C7: ='Revenue Model'!C8 | D7: ='Revenue Model'!D8 | E7: ='Revenue Model'!E8 | F7: ='Revenue Model'!F8 | G7: ='Revenue Model'!G8 | H7: ='Revenue Model'!H8 | I7: ='Revenue Model'!I8 | ... M7: ='Revenue Model'!M8 | N7: =SUM(B7:M7)
A8: Subscription revenue | B8: ='Revenue Model'!B13 | C8: ='Revenue Model'!C13 | D8: ='Revenue Model'!D13 | E8: ='Revenue Model'!E13 | F8: ='Revenue Model'!F13 | G8: ='Revenue Model'!G13 | H8: ='Revenue Model'!H13 | I8: ='Revenue Model'!I13 | ... M8: ='Revenue Model'!M13 | N8: =SUM(B8:M8)
A9: Sponsorship revenue (B2B) | B9: ='Revenue Model'!B18 | C9: ='Revenue Model'!C18 | D9: ='Revenue Model'!D18 | E9: ='Revenue Model'!E18 | F9: ='Revenue Model'!F18 | G9: ='Revenue Model'!G18 | H9: ='Revenue Model'!H18 | I9: ='Revenue Model'!I18 | ... M9: ='Revenue Model'!M18 | N9: =SUM(B9:M9)
A10: Total Revenue | B10: =B7+B8+B9 | C10: =C7+C8+C9 | D10: =D7+D8+D9 | E10: =E7+E8+E9 | F10: =F7+F8+F9 | G10: =G7+G8+G9 | H10: =H7+H8+H9 | I10: =I7+I8+I9 | ... M10: =M7+M8+M9 | N10: =SUM(B10:M10)
A12: Cost of revenue
A13: Payment-gateway fees | B13: ='Revenue Model'!B9 | C13: ='Revenue Model'!C9 | D13: ='Revenue Model'!D9 | E13: ='Revenue Model'!E9 | F13: ='Revenue Model'!F9 | G13: ='Revenue Model'!G9 | H13: ='Revenue Model'!H9 | I13: ='Revenue Model'!I9 | ... M13: ='Revenue Model'!M9 | N13: =SUM(B13:M13)
A14: Gross Profit | B14: =B10-B13 | C14: =C10-C13 | D14: =D10-D13 | E14: =E10-E13 | F14: =F10-F13 | G14: =G10-G13 | H14: =H10-H13 | I14: =I10-I13 | ... M14: =M10-M13 | N14: =SUM(B14:M14)
A15: Gross Margin % | B15: =IFERROR(B14/B10,"") | C15: =IFERROR(C14/C10,"") | D15: =IFERROR(D14/D10,"") | E15: =IFERROR(E14/E10,"") | F15: =IFERROR(F14/F10,"") | G15: =IFERROR(G14/G10,"") | H15: =IFERROR(H14/H10,"") | I15: =IFERROR(I14/I10,"") | ... M15: =IFERROR(M14/M10,"")
A17: Operating expenses — team (5 founders unpaid)
A18: Designer 1 | B18: =Assumptions!$C$64 | C18: =Assumptions!$C$64 | D18: =Assumptions!$C$64 | E18: =Assumptions!$C$64 | F18: =Assumptions!$C$64 | G18: =Assumptions!$C$64 | H18: =Assumptions!$C$64 | I18: =Assumptions!$C$64 | ... M18: =Assumptions!$C$64 | N18: =SUM(B18:M18)
A19: Designer 2 | B19: =Assumptions!$C$65 | C19: =Assumptions!$C$65 | D19: =Assumptions!$C$65 | E19: =Assumptions!$C$65 | F19: =Assumptions!$C$65 | G19: =Assumptions!$C$65 | H19: =Assumptions!$C$65 | I19: =Assumptions!$C$65 | ... M19: =Assumptions!$C$65 | N19: =SUM(B19:M19)
A20: Financial analyst | B20: =Assumptions!$C$66 | C20: =Assumptions!$C$66 | D20: =Assumptions!$C$66 | E20: =Assumptions!$C$66 | F20: =Assumptions!$C$66 | G20: =Assumptions!$C$66 | H20: =Assumptions!$C$66 | I20: =Assumptions!$C$66 | ... M20: =Assumptions!$C$66 | N20: =SUM(B20:M20)
A21: Growth hire (from Month 3) | B21: =IF(B$4>=Assumptions!$C$68,Assumptions!$C$67,0) | C21: =IF(C$4>=Assumptions!$C$68,Assumptions!$C$67,0) | D21: =IF(D$4>=Assumptions!$C$68,Assumptions!$C$67,0) | E21: =IF(E$4>=Assumptions!$C$68,Assumptions!$C$67,0) | F21: =IF(F$4>=Assumptions!$C$68,Assumptions!$C$67,0) | G21: =IF(G$4>=Assumptions!$C$68,Assumptions!$C$67,0) | H21: =IF(H$4>=Assumptions!$C$68,Assumptions!$C$67,0) | I21: =IF(I$4>=Assumptions!$C$68,Assumptions!$C$67,0) | ... M21: =IF(M$4>=Assumptions!$C$68,Assumptions!$C$67,0) | N21: =SUM(B21:M21)
A22: Ops hire (from Month 6) | B22: =IF(B$4>=Assumptions!$C$70,Assumptions!$C$69,0) | C22: =IF(C$4>=Assumptions!$C$70,Assumptions!$C$69,0) | D22: =IF(D$4>=Assumptions!$C$70,Assumptions!$C$69,0) | E22: =IF(E$4>=Assumptions!$C$70,Assumptions!$C$69,0) | F22: =IF(F$4>=Assumptions!$C$70,Assumptions!$C$69,0) | G22: =IF(G$4>=Assumptions!$C$70,Assumptions!$C$69,0) | H22: =IF(H$4>=Assumptions!$C$70,Assumptions!$C$69,0) | I22: =IF(I$4>=Assumptions!$C$70,Assumptions!$C$69,0) | ... M22: =IF(M$4>=Assumptions!$C$70,Assumptions!$C$69,0) | N22: =SUM(B22:M22)
A23: Total salaries | B23: =SUM(B18:B22) | C23: =SUM(C18:C22) | D23: =SUM(D18:D22) | E23: =SUM(E18:E22) | F23: =SUM(F18:F22) | G23: =SUM(G18:G22) | H23: =SUM(H18:H22) | I23: =SUM(I18:I22) | ... M23: =SUM(M18:M22) | N23: =SUM(B23:M23)
A25: Operating expenses — acquisition & marketing
A26: Generic paid (ads + ambassadors) | B26: =Assumptions!$C$19 | C26: =Assumptions!$C$19 | D26: =Assumptions!$C$19 | E26: =Assumptions!$C$19 | F26: =Assumptions!$C$19 | G26: =Assumptions!$C$19 | H26: =Assumptions!$C$19 | I26: =Assumptions!$C$19 | ... M26: =Assumptions!$C$19 | N26: =SUM(B26:M26)
A27: Creator-partnership spend | B27: =IF(B$4<Assumptions!$C$28,0,IF(B$4<Assumptions!$C$32,Assumptions!$C$31,Assumptions!$C$33))*Assumptions!$C$29 | C27: =IF(C$4<Assumptions!$C$28,0,IF(C$4<Assumptions!$C$32,Assumptions!$C$31,Assumptions!$C$33))*Assumptions!$C$29 | D27: =IF(D$4<Assumptions!$C$28,0,IF(D$4<Assumptions!$C$32,Assumptions!$C$31,Assumptions!$C$33))*Assumptions!$C$29 | E27: =IF(E$4<Assumptions!$C$28,0,IF(E$4<Assumptions!$C$32,Assumptions!$C$31,Assumptions!$C$33))*Assumptions!$C$29 | F27: =IF(F$4<Assumptions!$C$28,0,IF(F$4<Assumptions!$C$32,Assumptions!$C$31,Assumptions!$C$33))*Assumptions!$C$29 | G27: =IF(G$4<Assumptions!$C$28,0,IF(G$4<Assumptions!$C$32,Assumptions!$C$31,Assumptions!$C$33))*Assumptions!$C$29 | H27: =IF(H$4<Assumptions!$C$28,0,IF(H$4<Assumptions!$C$32,Assumptions!$C$31,Assumptions!$C$33))*Assumptions!$C$29 | I27: =IF(I$4<Assumptions!$C$28,0,IF(I$4<Assumptions!$C$32,Assumptions!$C$31,Assumptions!$C$33))*Assumptions!$C$29 | ... M27: =IF(M$4<Assumptions!$C$28,0,IF(M$4<Assumptions!$C$32,Assumptions!$C$31,Assumptions!$C$33))*Assumptions!$C$29 | N27: =SUM(B27:M27)
A28: Host-sponsorship spend | B28: =IF(B$4<Assumptions!$C$36,0,Assumptions!$C$37)*Assumptions!$C$38 | C28: =IF(C$4<Assumptions!$C$36,0,Assumptions!$C$37)*Assumptions!$C$38 | D28: =IF(D$4<Assumptions!$C$36,0,Assumptions!$C$37)*Assumptions!$C$38 | E28: =IF(E$4<Assumptions!$C$36,0,Assumptions!$C$37)*Assumptions!$C$38 | F28: =IF(F$4<Assumptions!$C$36,0,Assumptions!$C$37)*Assumptions!$C$38 | G28: =IF(G$4<Assumptions!$C$36,0,Assumptions!$C$37)*Assumptions!$C$38 | H28: =IF(H$4<Assumptions!$C$36,0,Assumptions!$C$37)*Assumptions!$C$38 | I28: =IF(I$4<Assumptions!$C$36,0,Assumptions!$C$37)*Assumptions!$C$38 | ... M28: =IF(M$4<Assumptions!$C$36,0,Assumptions!$C$37)*Assumptions!$C$38 | N28: =SUM(B28:M28)
A29: Total acquisition & marketing | B29: =B26+B27+B28 | C29: =C26+C27+C28 | D29: =D26+D27+D28 | E29: =E26+E27+E28 | F29: =F26+F27+F28 | G29: =G26+G27+G28 | H29: =H26+H27+H28 | I29: =I26+I27+I28 | ... M29: =M26+M27+M28 | N29: =SUM(B29:M29)
A31: Operating expenses — other
A32: Other recurring opex | B32: =Assumptions!$C$71 | C32: =Assumptions!$C$71 | D32: =Assumptions!$C$71 | E32: =Assumptions!$C$71 | F32: =Assumptions!$C$71 | G32: =Assumptions!$C$71 | H32: =Assumptions!$C$71 | I32: =Assumptions!$C$71 | ... M32: =Assumptions!$C$71 | N32: =SUM(B32:M32)
A33: One-time: 2nd-city launch | B33: =IF(B$4=Assumptions!$C$23,Assumptions!$C$24,0) | C33: =IF(C$4=Assumptions!$C$23,Assumptions!$C$24,0) | D33: =IF(D$4=Assumptions!$C$23,Assumptions!$C$24,0) | E33: =IF(E$4=Assumptions!$C$23,Assumptions!$C$24,0) | F33: =IF(F$4=Assumptions!$C$23,Assumptions!$C$24,0) | G33: =IF(G$4=Assumptions!$C$23,Assumptions!$C$24,0) | H33: =IF(H$4=Assumptions!$C$23,Assumptions!$C$24,0) | I33: =IF(I$4=Assumptions!$C$23,Assumptions!$C$24,0) | ... M33: =IF(M$4=Assumptions!$C$23,Assumptions!$C$24,0) | N33: =SUM(B33:M33)
A34: Total Operating Expenses | B34: =B23+B29+B32+B33 | C34: =C23+C29+C32+C33 | D34: =D23+D29+D32+D33 | E34: =E23+E29+E32+E33 | F34: =F23+F29+F32+F33 | G34: =G23+G29+G32+G33 | H34: =H23+H29+H32+H33 | I34: =I23+I29+I32+I33 | ... M34: =M23+M29+M32+M33 | N34: =SUM(B34:M34)
A36: Profitability
A37: EBITDA | B37: =B14-B34 | C37: =C14-C34 | D37: =D14-D34 | E37: =E14-E34 | F37: =F14-F34 | G37: =G14-G34 | H37: =H14-H34 | I37: =I14-I34 | ... M37: =M14-M34 | N37: =SUM(B37:M37)
A38: EBITDA Margin % | B38: =IFERROR(B37/B10,"") | C38: =IFERROR(C37/C10,"") | D38: =IFERROR(D37/D10,"") | E38: =IFERROR(E37/E10,"") | F38: =IFERROR(F37/F10,"") | G38: =IFERROR(G37/G10,"") | H38: =IFERROR(H37/H10,"") | I38: =IFERROR(I37/I10,"") | ... M38: =IFERROR(M37/M10,"")
A40: Memo — YC AI Stack credits (non-cash, nets to zero)
A41: Infrastructure cost, in-kind | B41: =Assumptions!$C$77+(Assumptions!$C$78-Assumptions!$C$77)*(B$4-1)/11 | C41: =Assumptions!$C$77+(Assumptions!$C$78-Assumptions!$C$77)*(C$4-1)/11 | D41: =Assumptions!$C$77+(Assumptions!$C$78-Assumptions!$C$77)*(D$4-1)/11 | E41: =Assumptions!$C$77+(Assumptions!$C$78-Assumptions!$C$77)*(E$4-1)/11 | F41: =Assumptions!$C$77+(Assumptions!$C$78-Assumptions!$C$77)*(F$4-1)/11 | G41: =Assumptions!$C$77+(Assumptions!$C$78-Assumptions!$C$77)*(G$4-1)/11 | H41: =Assumptions!$C$77+(Assumptions!$C$78-Assumptions!$C$77)*(H$4-1)/11 | I41: =Assumptions!$C$77+(Assumptions!$C$78-Assumptions!$C$77)*(I$4-1)/11 | ... M41: =Assumptions!$C$77+(Assumptions!$C$78-Assumptions!$C$77)*(M$4-1)/11
A42: Grant income recognized | B42: =B41 | C42: =C41 | D42: =D41 | E42: =E41 | F42: =F41 | G42: =G41 | H42: =H41 | I42: =I41 | ... M42: =M41
A43: Net P&L impact of YC credits | B43: =B42-B41 | C43: =C42-C41 | D43: =D42-D41 | E43: =E42-E41 | F43: =F42-F41 | G43: =G42-G41 | H43: =H42-H41 | I43: =I42-I41 | ... M43: =M42-M41
A45: Net Income | B45: =B37+B43 | C45: =C37+C43 | D45: =D37+D43 | E45: =E37+E43 | F45: =F37+F43 | G45: =G37+G43 | H45: =H37+H43 | I45: =I37+I43 | ... M45: =M37+M43 | N45: =SUM(B45:M45)
A46: Cumulative Net Income | B46: =B45 | C46: =B46+C45 | D46: =C46+D45 | E46: =D46+E45 | F46: =E46+F45 | G46: =F46+G45 | H46: =G46+H45 | I46: =H46+I45 | J46: =I46+J45 | ... M46: =L46+M45 | N46: =M46
A47: Profitable flag (helper) | B47: =IF(B45>=0,1,0) | C47: =IF(C45>=0,1,0) | D47: =IF(D45>=0,1,0) | E47: =IF(E45>=0,1,0) | F47: =IF(F45>=0,1,0) | G47: =IF(G45>=0,1,0) | H47: =IF(H45>=0,1,0) | I47: =IF(I45>=0,1,0) | ... M47: =IF(M45>=0,1,0)

Sheet Cash Flow
A1: Cash Flow Statement
A2: Monthly cash flow with founder-loan draws covering any shortfall.
A4: (₹000s) | B4: 1 | C4: 2 | D4: 3 | E4: 4 | F4: 5 | G4: 6 | H4: 7 | I4: 8 | J4: 9 | K4: 10 | L4: 11 | M4: 12 | N4: FY1
A6: Operating activities
A7: Net income | B7: ='Income Statement'!B45 | C7: ='Income Statement'!C45 | D7: ='Income Statement'!D45 | E7: ='Income Statement'!E45 | F7: ='Income Statement'!F45 | G7: ='Income Statement'!G45 | H7: ='Income Statement'!H45 | I7: ='Income Statement'!I45 | ... M7: ='Income Statement'!M45 | N7: =SUM(B7:M7)
A8: Non-cash adjustments (YC grant/infra) | B8: ='Income Statement'!B43-'Income Statement'!B43 | C8: ='Income Statement'!C43-'Income Statement'!C43 | D8: ='Income Statement'!D43-'Income Statement'!D43 | E8: ='Income Statement'!E43-'Income Statement'!E43 | F8: ='Income Statement'!F43-'Income Statement'!F43 | G8: ='Income Statement'!G43-'Income Statement'!G43 | H8: ='Income Statement'!H43-'Income Statement'!H43 | I8: ='Income Statement'!I43-'Income Statement'!I43 | ... M8: ='Income Statement'!M43-'Income Statement'!M43 | N8: =SUM(B8:M8)
A9: Cash flow from operations | B9: =B7+B8 | C9: =C7+C8 | D9: =D7+D8 | E9: =E7+E8 | F9: =F7+F8 | G9: =G7+G8 | H9: =H7+H8 | I9: =I7+I8 | ... M9: =M7+M8 | N9: =SUM(B9:M9)
A11: Financing activities
A12: Beginning cash | B12: =Assumptions!$C$81 | C12: =B14 | D12: =C14 | E12: =D14 | F12: =E14 | G12: =F14 | H12: =G14 | I12: =H14 | J12: =I14 | ... M12: =L14
A13: Founder loan drawn | B13: =MAX(0,-(B12+B9)) | C13: =MAX(0,-(C12+C9)) | D13: =MAX(0,-(D12+D9)) | E13: =MAX(0,-(E12+E9)) | F13: =MAX(0,-(F12+F9)) | G13: =MAX(0,-(G12+G9)) | H13: =MAX(0,-(H12+H9)) | I13: =MAX(0,-(I12+I9)) | ... M13: =MAX(0,-(M12+M9)) | N13: =SUM(B13:M13)
A14: Ending cash | B14: =B12+B9+B13 | C14: =C12+C9+C13 | D14: =D12+D9+D13 | E14: =E12+E9+E13 | F14: =F12+F9+F13 | G14: =G12+G9+G13 | H14: =H12+H9+H13 | I14: =I12+I9+I13 | ... M14: =M12+M9+M13 | N14: =M14
A15: Cumulative founder loan outstanding | B15: =B13 | C15: =B15+C13 | D15: =C15+D13 | E15: =D15+E13 | F15: =E15+F13 | G15: =F15+G13 | H15: =G15+H13 | I15: =H15+I13 | J15: =I15+J13 | ... M15: =L15+M13 | N15: =M15

Sheet Balance Sheet
A1: Balance Sheet
A2: Monthly snapshot. Assets = Liabilities + Equity in every column (see balance check row).
A4: (₹000s) | B4: 1 | C4: 2 | D4: 3 | E4: 4 | F4: 5 | G4: 6 | H4: 7 | I4: 8 | J4: 9 | K4: 10 | L4: 11 | M4: 12 | N4: FY1
A6: Assets
A7: Cash | B7: ='Cash Flow'!B14 | C7: ='Cash Flow'!C14 | D7: ='Cash Flow'!D14 | E7: ='Cash Flow'!E14 | F7: ='Cash Flow'!F14 | G7: ='Cash Flow'!G14 | H7: ='Cash Flow'!H14 | I7: ='Cash Flow'!I14 | ... M7: ='Cash Flow'!M14 | N7: =M7
A8: Infra cost this month | B8: ='Income Statement'!B41 | C8: ='Income Statement'!C41 | D8: ='Income Statement'!D41 | E8: ='Income Statement'!E41 | F8: ='Income Statement'!F41 | G8: ='Income Statement'!G41 | H8: ='Income Statement'!H41 | I8: ='Income Statement'!I41 | ... M8: ='Income Statement'!M41
A9: Cumulative YC infra credits used | B9: =B8 | C9: =B9+C8 | D9: =C9+D8 | E9: =D9+E8 | F9: =E9+F8 | G9: =F9+G8 | H9: =G9+H8 | I9: =H9+I8 | J9: =I9+J8 | ... M9: =L9+M8 | N9: =M9
A10: YC AI Stack credit remaining | B10: =Assumptions!$C$76-B9 | C10: =Assumptions!$C$76-C9 | D10: =Assumptions!$C$76-D9 | E10: =Assumptions!$C$76-E9 | F10: =Assumptions!$C$76-F9 | G10: =Assumptions!$C$76-G9 | H10: =Assumptions!$C$76-H9 | I10: =Assumptions!$C$76-I9 | ... M10: =Assumptions!$C$76-M9 | N10: =M10
A11: Total Assets | B11: =B7+B10 | C11: =C7+C10 | D11: =D7+D10 | E11: =E7+E10 | F11: =F7+F10 | G11: =G7+G10 | H11: =H7+H10 | I11: =I7+I10 | ... M11: =M7+M10 | N11: =M11
A13: Liabilities
A14: Due to founders (loan) | B14: =Assumptions!$C$72+'Cash Flow'!B15 | C14: =Assumptions!$C$72+'Cash Flow'!C15 | D14: =Assumptions!$C$72+'Cash Flow'!D15 | E14: =Assumptions!$C$72+'Cash Flow'!E15 | F14: =Assumptions!$C$72+'Cash Flow'!F15 | G14: =Assumptions!$C$72+'Cash Flow'!G15 | H14: =Assumptions!$C$72+'Cash Flow'!H15 | I14: =Assumptions!$C$72+'Cash Flow'!I15 | ... M14: =Assumptions!$C$72+'Cash Flow'!M15 | N14: =M14
A15: Deferred YC grant | B15: =B10 | C15: =C10 | D15: =D10 | E15: =E10 | F15: =F10 | G15: =G10 | H15: =H10 | I15: =I10 | ... M15: =M10 | N15: =M15
A16: Total Liabilities | B16: =B14+B15 | C16: =C14+C15 | D16: =D14+D15 | E16: =E14+E15 | F16: =F14+F15 | G16: =G14+G15 | H16: =H14+H15 | I16: =I14+I15 | ... M16: =M14+M15 | N16: =M16
A18: Equity
A19: Paid-in capital | B19: =Assumptions!$C$82 | C19: =Assumptions!$C$82 | D19: =Assumptions!$C$82 | E19: =Assumptions!$C$82 | F19: =Assumptions!$C$82 | G19: =Assumptions!$C$82 | H19: =Assumptions!$C$82 | I19: =Assumptions!$C$82 | ... M19: =Assumptions!$C$82
A20: Accumulated deficit | B20: =-Assumptions!$C$72+'Income Statement'!B46 | C20: =-Assumptions!$C$72+'Income Statement'!C46 | D20: =-Assumptions!$C$72+'Income Statement'!D46 | E20: =-Assumptions!$C$72+'Income Statement'!E46 | F20: =-Assumptions!$C$72+'Income Statement'!F46 | G20: =-Assumptions!$C$72+'Income Statement'!G46 | H20: =-Assumptions!$C$72+'Income Statement'!H46 | I20: =-Assumptions!$C$72+'Income Statement'!I46 | ... M20: =-Assumptions!$C$72+'Income Statement'!M46 | N20: =M20
A21: Total Equity | B21: =B19+B20 | C21: =C19+C20 | D21: =D19+D20 | E21: =E19+E20 | F21: =F19+F20 | G21: =G19+G20 | H21: =H19+H20 | I21: =I19+I20 | ... M21: =M19+M20 | N21: =M21
A23: Balance check (Assets − Liab − Equity) | B23: =B11-B16-B21 | C23: =C11-C16-C21 | D23: =D11-D16-D21 | E23: =E11-E16-E21 | F23: =F11-F16-F21 | G23: =G11-G16-G21 | H23: =H11-H16-H21 | I23: =I11-I16-I21 | ... M23: =M11-M16-M21 | N23: =M23

Sheet Unit Economics & Break-Even
A1: Unit Economics & Break-Even
A2: ARPU, CAC, LTV, payback, and the monthly gap to break-even.
A4: (₹000s) | B4: 1 | C4: 2 | D4: 3 | E4: 4 | F4: 5 | G4: 6 | H4: 7 | I4: 8 | J4: 9 | K4: 10 | L4: 11 | M4: 12 | N4: FY1
A6: Unit economics (per active user)
A7: ARPU / month | B7: =IFERROR('Income Statement'!B10/'Users & Growth'!B16,"") | C7: =IFERROR('Income Statement'!C10/'Users & Growth'!C16,"") | D7: =IFERROR('Income Statement'!D10/'Users & Growth'!D16,"") | E7: =IFERROR('Income Statement'!E10/'Users & Growth'!E16,"") | F7: =IFERROR('Income Statement'!F10/'Users & Growth'!F16,"") | G7: =IFERROR('Income Statement'!G10/'Users & Growth'!G16,"") | H7: =IFERROR('Income Statement'!H10/'Users & Growth'!H16,"") | I7: =IFERROR('Income Statement'!I10/'Users & Growth'!I16,"") | ... M7: =IFERROR('Income Statement'!M10/'Users & Growth'!M16,"")
A8: Gross profit / active user / month | B8: =IFERROR('Income Statement'!B14/'Users & Growth'!B16,"") | C8: =IFERROR('Income Statement'!C14/'Users & Growth'!C16,"") | D8: =IFERROR('Income Statement'!D14/'Users & Growth'!D16,"") | E8: =IFERROR('Income Statement'!E14/'Users & Growth'!E16,"") | F8: =IFERROR('Income Statement'!F14/'Users & Growth'!F16,"") | G8: =IFERROR('Income Statement'!G14/'Users & Growth'!G16,"") | H8: =IFERROR('Income Statement'!H14/'Users & Growth'!H16,"") | I8: =IFERROR('Income Statement'!I14/'Users & Growth'!I16,"") | ... M8: =IFERROR('Income Statement'!M14/'Users & Growth'!M16,"")
A9: Avg customer lifetime, months = 1÷churn (phased) | B9: =1/IF(B$4>=Assumptions!$C$90,Assumptions!$C$93,Assumptions!$C$42) | C9: =1/IF(C$4>=Assumptions!$C$90,Assumptions!$C$93,Assumptions!$C$42) | D9: =1/IF(D$4>=Assumptions!$C$90,Assumptions!$C$93,Assumptions!$C$42) | E9: =1/IF(E$4>=Assumptions!$C$90,Assumptions!$C$93,Assumptions!$C$42) | F9: =1/IF(F$4>=Assumptions!$C$90,Assumptions!$C$93,Assumptions!$C$42) | G9: =1/IF(G$4>=Assumptions!$C$90,Assumptions!$C$93,Assumptions!$C$42) | H9: =1/IF(H$4>=Assumptions!$C$90,Assumptions!$C$93,Assumptions!$C$42) | I9: =1/IF(I$4>=Assumptions!$C$90,Assumptions!$C$93,Assumptions!$C$42) | ... M9: =1/IF(M$4>=Assumptions!$C$90,Assumptions!$C$93,Assumptions!$C$42)
A10: LTV (lifetime gross profit) | B10: =B8*B9 | C10: =C8*C9 | D10: =D8*D9 | E10: =E8*E9 | F10: =F8*F9 | G10: =G8*G9 | H10: =H8*H9 | I10: =I8*I9 | ... M10: =M8*M9
A11: Blended CAC, all channels | B11: =IFERROR('Income Statement'!B29/'Users & Growth'!B12,"") | C11: =IFERROR('Income Statement'!C29/'Users & Growth'!C12,"") | D11: =IFERROR('Income Statement'!D29/'Users & Growth'!D12,"") | E11: =IFERROR('Income Statement'!E29/'Users & Growth'!E12,"") | F11: =IFERROR('Income Statement'!F29/'Users & Growth'!F12,"") | G11: =IFERROR('Income Statement'!G29/'Users & Growth'!G12,"") | H11: =IFERROR('Income Statement'!H29/'Users & Growth'!H12,"") | I11: =IFERROR('Income Statement'!I29/'Users & Growth'!I12,"") | ... M11: =IFERROR('Income Statement'!M29/'Users & Growth'!M12,"")
A12: generic paid | B12: =IFERROR('Income Statement'!B26/'Users & Growth'!B12,"") | C12: =IFERROR('Income Statement'!C26/'Users & Growth'!C12,"") | D12: =IFERROR('Income Statement'!D26/'Users & Growth'!D12,"") | E12: =IFERROR('Income Statement'!E26/'Users & Growth'!E12,"") | F12: =IFERROR('Income Statement'!F26/'Users & Growth'!F12,"") | G12: =IFERROR('Income Statement'!G26/'Users & Growth'!G12,"") | H12: =IFERROR('Income Statement'!H26/'Users & Growth'!H12,"") | I12: =IFERROR('Income Statement'!I26/'Users & Growth'!I12,"") | ... M12: =IFERROR('Income Statement'!M26/'Users & Growth'!M12,"")
A13: creator partnerships | B13: =IFERROR('Income Statement'!B27/'Users & Growth'!B12,"") | C13: =IFERROR('Income Statement'!C27/'Users & Growth'!C12,"") | D13: =IFERROR('Income Statement'!D27/'Users & Growth'!D12,"") | E13: =IFERROR('Income Statement'!E27/'Users & Growth'!E12,"") | F13: =IFERROR('Income Statement'!F27/'Users & Growth'!F12,"") | G13: =IFERROR('Income Statement'!G27/'Users & Growth'!G12,"") | H13: =IFERROR('Income Statement'!H27/'Users & Growth'!H12,"") | I13: =IFERROR('Income Statement'!I27/'Users & Growth'!I12,"") | ... M13: =IFERROR('Income Statement'!M27/'Users & Growth'!M12,"")
A14: host sponsorship | B14: =IFERROR('Income Statement'!B28/'Users & Growth'!B12,"") | C14: =IFERROR('Income Statement'!C28/'Users & Growth'!C12,"") | D14: =IFERROR('Income Statement'!D28/'Users & Growth'!D12,"") | E14: =IFERROR('Income Statement'!E28/'Users & Growth'!E12,"") | F14: =IFERROR('Income Statement'!F28/'Users & Growth'!F12,"") | G14: =IFERROR('Income Statement'!G28/'Users & Growth'!G12,"") | H14: =IFERROR('Income Statement'!H28/'Users & Growth'!H12,"") | I14: =IFERROR('Income Statement'!I28/'Users & Growth'!I12,"") | ... M14: =IFERROR('Income Statement'!M28/'Users & Growth'!M12,"")
A15: LTV : CAC (activation-adjusted) | B15: =IFERROR(B10*IF(B$4>=Assumptions!$C$90,Assumptions!$C$91,Assumptions!$C$43)/B11,"") | C15: =IFERROR(C10*IF(C$4>=Assumptions!$C$90,Assumptions!$C$91,Assumptions!$C$43)/C11,"") | D15: =IFERROR(D10*IF(D$4>=Assumptions!$C$90,Assumptions!$C$91,Assumptions!$C$43)/D11,"") | E15: =IFERROR(E10*IF(E$4>=Assumptions!$C$90,Assumptions!$C$91,Assumptions!$C$43)/E11,"") | F15: =IFERROR(F10*IF(F$4>=Assumptions!$C$90,Assumptions!$C$91,Assumptions!$C$43)/F11,"") | G15: =IFERROR(G10*IF(G$4>=Assumptions!$C$90,Assumptions!$C$91,Assumptions!$C$43)/G11,"") | H15: =IFERROR(H10*IF(H$4>=Assumptions!$C$90,Assumptions!$C$91,Assumptions!$C$43)/H11,"") | I15: =IFERROR(I10*IF(I$4>=Assumptions!$C$90,Assumptions!$C$91,Assumptions!$C$43)/I11,"") | ... M15: =IFERROR(M10*IF(M$4>=Assumptions!$C$90,Assumptions!$C$91,Assumptions!$C$43)/M11,"")
A16: CAC payback, months (activation-adj) | B16: =IFERROR(B11/(B8*IF(B$4>=Assumptions!$C$90,Assumptions!$C$91,Assumptions!$C$43)),"") | C16: =IFERROR(C11/(C8*IF(C$4>=Assumptions!$C$90,Assumptions!$C$91,Assumptions!$C$43)),"") | D16: =IFERROR(D11/(D8*IF(D$4>=Assumptions!$C$90,Assumptions!$C$91,Assumptions!$C$43)),"") | E16: =IFERROR(E11/(E8*IF(E$4>=Assumptions!$C$90,Assumptions!$C$91,Assumptions!$C$43)),"") | F16: =IFERROR(F11/(F8*IF(F$4>=Assumptions!$C$90,Assumptions!$C$91,Assumptions!$C$43)),"") | G16: =IFERROR(G11/(G8*IF(G$4>=Assumptions!$C$90,Assumptions!$C$91,Assumptions!$C$43)),"") | H16: =IFERROR(H11/(H8*IF(H$4>=Assumptions!$C$90,Assumptions!$C$91,Assumptions!$C$43)),"") | I16: =IFERROR(I11/(I8*IF(I$4>=Assumptions!$C$90,Assumptions!$C$91,Assumptions!$C$43)),"") | ... M16: =IFERROR(M11/(M8*IF(M$4>=Assumptions!$C$90,Assumptions!$C$91,Assumptions!$C$43)),"")
A18: Acquisition channel comparison
A19: Creator deal: cost / signup (pre-verification) | B19: =Assumptions!$C$29/Assumptions!$C$30 | C19: =Assumptions!$C$29/Assumptions!$C$30 | D19: =Assumptions!$C$29/Assumptions!$C$30 | E19: =Assumptions!$C$29/Assumptions!$C$30 | F19: =Assumptions!$C$29/Assumptions!$C$30 | G19: =Assumptions!$C$29/Assumptions!$C$30 | H19: =Assumptions!$C$29/Assumptions!$C$30 | I19: =Assumptions!$C$29/Assumptions!$C$30 | ... M19: =Assumptions!$C$29/Assumptions!$C$30
A20: Sponsored event: cost / signup (pre-verification) | B20: =Assumptions!$C$38/Assumptions!$C$39 | C20: =Assumptions!$C$38/Assumptions!$C$39 | D20: =Assumptions!$C$38/Assumptions!$C$39 | E20: =Assumptions!$C$38/Assumptions!$C$39 | F20: =Assumptions!$C$38/Assumptions!$C$39 | G20: =Assumptions!$C$38/Assumptions!$C$39 | H20: =Assumptions!$C$38/Assumptions!$C$39 | I20: =Assumptions!$C$38/Assumptions!$C$39 | ... M20: =Assumptions!$C$38/Assumptions!$C$39
A22: Break-even analysis
A23: Fixed costs / month | B23: ='Income Statement'!B23+'Income Statement'!B29+'Income Statement'!B32 | C23: ='Income Statement'!C23+'Income Statement'!C29+'Income Statement'!C32 | D23: ='Income Statement'!D23+'Income Statement'!D29+'Income Statement'!D32 | E23: ='Income Statement'!E23+'Income Statement'!E29+'Income Statement'!E32 | F23: ='Income Statement'!F23+'Income Statement'!F29+'Income Statement'!F32 | G23: ='Income Statement'!G23+'Income Statement'!G29+'Income Statement'!G32 | H23: ='Income Statement'!H23+'Income Statement'!H29+'Income Statement'!H32 | I23: ='Income Statement'!I23+'Income Statement'!I29+'Income Statement'!I32 | ... M23: ='Income Statement'!M23+'Income Statement'!M29+'Income Statement'!M32
A24: Contribution margin % | B24: ='Income Statement'!B15 | C24: ='Income Statement'!C15 | D24: ='Income Statement'!D15 | E24: ='Income Statement'!E15 | F24: ='Income Statement'!F15 | G24: ='Income Statement'!G15 | H24: ='Income Statement'!H15 | I24: ='Income Statement'!I15 | ... M24: ='Income Statement'!M15
A25: Break-even revenue required | B25: =IFERROR(B23/B24,"") | C25: =IFERROR(C23/C24,"") | D25: =IFERROR(D23/D24,"") | E25: =IFERROR(E23/E24,"") | F25: =IFERROR(F23/F24,"") | G25: =IFERROR(G23/G24,"") | H25: =IFERROR(H23/H24,"") | I25: =IFERROR(I23/I24,"") | ... M25: =IFERROR(M23/M24,"")
A26: Break-even active users required | B26: =IFERROR(B25/B7,"") | C26: =IFERROR(C25/C7,"") | D26: =IFERROR(D25/D7,"") | E26: =IFERROR(E25/E7,"") | F26: =IFERROR(F25/F7,"") | G26: =IFERROR(G25/G7,"") | H26: =IFERROR(H25/H7,"") | I26: =IFERROR(I25/I7,"") | ... M26: =IFERROR(M25/M7,"")
A27: Revenue vs. break-even (gap) | B27: ='Income Statement'!B10-B25 | C27: ='Income Statement'!C10-C25 | D27: ='Income Statement'!D10-D25 | E27: ='Income Statement'!E10-E25 | F27: ='Income Statement'!F10-F25 | G27: ='Income Statement'!G10-G25 | H27: ='Income Statement'!H10-H25 | I27: ='Income Statement'!I10-I25 | ... M27: ='Income Statement'!M10-M25
A28: % of break-even achieved | B28: =IFERROR('Income Statement'!B10/B25,"") | C28: =IFERROR('Income Statement'!C10/C25,"") | D28: =IFERROR('Income Statement'!D10/D25,"") | E28: =IFERROR('Income Statement'!E10/E25,"") | F28: =IFERROR('Income Statement'!F10/F25,"") | G28: =IFERROR('Income Statement'!G10/G25,"") | H28: =IFERROR('Income Statement'!H10/H25,"") | I28: =IFERROR('Income Statement'!I10/I25,"") | ... M28: =IFERROR('Income Statement'!M10/M25,"")

Sheet Financial Ratios
A1: Financial Ratios & Key Metrics
A2: Year 1 summary. Every figure links back to the detail sheets.
A4: Scale — Month 12 vs Month 0
A5: Verified users, Month 0 | C5: =Assumptions!$C$11
A6: Verified users, Month 12 (cumulative) | C6: ='Users & Growth'!M13
A7: Active users, Month 0 | C7: =Assumptions!$C$13
A8: Active users, Month 12 | C8: ='Users & Growth'!M16
A10: Revenue
A11: Year 1 Total Revenue | C11: ='Income Statement'!N10
A12: Month 1 Revenue | C12: ='Income Statement'!B10
A13: Month 12 Revenue | C13: ='Income Statement'!M10
A14: Revenue growth, Month 12 vs 1 | C14: =IFERROR('Income Statement'!M10/'Income Statement'!B10,"")
A15: Month 12 Gross Margin % | C15: ='Income Statement'!M15
A17: Acquisition spend — Year 1 split by channel
A18: Generic paid ads/ambassadors | C18: ='Income Statement'!N26
A19: Creator partnerships | C19: ='Income Statement'!N27
A20: r/girlshangouthyd host sponsorship | C20: ='Income Statement'!N28
A21: Total acquisition spend, Year 1 | C21: ='Income Statement'!N29
A23: Burn & funding
A24: Year 1 Total Operating Expenses | C24: ='Income Statement'!N34
A25: Year 1 Net Loss | C25: ='Income Statement'!N45
A26: Average monthly burn, Year 1 | C26: =ABS('Income Statement'!N45)/12
A27: Month 12 monthly burn rate | C27: =-'Income Statement'!M45
A28: Founder funding required through Month 12 | C28: ='Balance Sheet'!M14
A29: Burn multiple, Year 1 | C29: =IFERROR(ABS('Income Statement'!N45)/'Income Statement'!N10,"")
A31: Unit economics — Month 12 read
A32: LTV | C32: ='Unit Economics & Break-Even'!M10
A33: Blended CAC, all channels | C33: ='Unit Economics & Break-Even'!M11
A34: LTV : CAC (activation-adj) | C34: ='Unit Economics & Break-Even'!M15
A35: CAC payback, months | C35: ='Unit Economics & Break-Even'!M16
A36: Cost/signup, creator deal | C36: ='Unit Economics & Break-Even'!M19
A37: Cost/signup, sponsored event | C37: ='Unit Economics & Break-Even'!M20
A39: Break-even
A40: First cash-flow-positive month | C40: =IFERROR(INDEX('Income Statement'!B4:M4,MATCH(1,'Income Statement'!B47:M47,0)),"Not reached within Month 12")
A41: Break-even active users, Month 12 | C41: ='Unit Economics & Break-Even'!M26
A42: Actual active users, Month 12 | C42: ='Users & Growth'!M16
A44: Team efficiency
A45: Paid headcount, Month 12 | C45: =5
A46: Revenue / paid employee, Month 12 (monthly) | C46: ='Income Statement'!M10/5

Sheet Cap Table
A1: Cap Table
A2: Pre-money. The pre-seed round in conversations is not yet reflected here.
A4: Holder | B4: Equity %
A5: Founder 1 | B5: =Assumptions!$C$86
A6: Founder 2 | B6: =Assumptions!$C$86
A7: Founder 3 | B7: =Assumptions!$C$86
A8: Founder 4 | B8: =Assumptions!$C$86
A9: Founder 5 | B9: =Assumptions!$C$86
A10: ESOP pool (unallocated) | B10: =Assumptions!$C$85
A11: Total | B11: =SUM(B5:B10)
